Workbook

Sheet Control
A1: Plan de pruebas — Freelance (rescate)
A2: Una fila por escenario. Las columnas de resultado se calculan desde cada hoja ESC-xx. Llenar en amarillo: Corrida actual y Responsable.
A4: ID | B4: Escenario | C4: Núm. original | D4: Módulo | E4: Objetivo | F4: Dependencias | G4: Sesión | H4: Pasos | I4: Legado Cumple | J4: Legado No cumple | K4: Legado Sin ejecutar | L4: Ejecutados | M4: CUMPLE | N4: % cumplimiento | O4: Estado | P4: Corrida actual | Q4: Hallazgos abiertos | R4: ⚠ Calidad del caso
A5: ESC-01 | B5: Pedido para Metropólitan (Seguridad) - Sin Cancelación | C5: Escenario 1 | D5: Pedidos | E5: Validar el alta completa de un pedido de Seguridad sin cancelación y su detalle, hasta la cancelación del pedido. | F5: — | G5: S01 | H5: 25 | I5: 17 | J5: 8 | K5: 0 | L5: ='ESC-01'!J3 | M5: ='ESC-01'!J4 | N5: ='ESC-01'!J5 | O5: =IF(H5=0,"Por definir",IF(N5=1,"✅ 100%",IF(L5=0,"Sin probar","En ciclo"))) | Q5: =COUNTIFS(Hallazgos!$B:$B,A5,Hallazgos!$M:$M,"<>Cerrado",Hallazgos!$A:$A,"<>") | R5: Paso 13: la descripción (prerellenos) y el esperado (productos de Seguridad) no corresponden.
A6: ESC-02 | B6: Pedido PRG-Producción con complejidad y días show | C6: Escenario 2 | D6: Pedidos | E6: Validar un pedido PRG con complejidad y días de show: personal Staff, bloques por producto y presupuesto ligado a complejidad. | F6: — | G6: S02 | H6: 26 | I6: 13 | J6: 6 | K6: 7 | L6: ='ESC-02'!J3 | M6: ='ESC-02'!J4 | N6: ='ESC-02'!J5 | O6: =IF(H6=0,"Por definir",IF(N6=1,"✅ 100%",IF(L6=0,"Sin probar","En ciclo"))) | P6: R1 | Q6: =COUNTIFS(Hallazgos!$B:$B,A6,Hallazgos!$M:$M,"<>Cerrado",Hallazgos!$A:$A,"<>") | R6: Paso 5 esperado dice 'UN de seguridad' (copiado del Esc. 1). Paso 7 texto corrupto ('movi+E10:F10miento'). Paso 8 es Servicio Interno pero el esperado habla de Pedido. Paso 18: 'nos' probablemente es 'no'.
A7: ESC-03 | B7: Pedido PRG-Producción con complejidad y fase de evento | C7: Escenario 3 | D7: Pedidos | E7: Validar un pedido PRG sin complejidad con varios detalles por fase de evento y arrastre de valores del detalle anterior. | F7: — | G7: S03 | H7: 32 | I7: 18 | J7: 12 | K7: 2 | L7: ='ESC-03'!J3 | M7: ='ESC-03'!J4 | N7: ='ESC-03'!J5 | O7: =IF(H7=0,"Por definir",IF(N7=1,"✅ 100%",IF(L7=0,"Sin probar","En ciclo"))) | Q7: =COUNTIFS(Hallazgos!$B:$B,A7,Hallazgos!$M:$M,"<>Cerrado",Hallazgos!$A:$A,"<>") | R7: Paso 5 marcado Cumple y No cumple a la vez; esperado dice 'UN de seguridad'. Paso 8: Servicio Interno con esperado de Pedido.
A8: ESC-04 | B8: Pedido para Azteca (Seguridad) - Futbol América vs Pumas | C8: Escenario 4 | D8: Pedidos | E8: Validar un pedido de Seguridad de gran volumen (9 productos) con alta repetitiva de detalles. | F8: — | G8: S04 | H8: 106 | I8: 25 | J8: 6 | K8: 75 | L8: ='ESC-04'!J3 | M8: ='ESC-04'!J4 | N8: ='ESC-04'!J5 | O8: =IF(H8=0,"Por definir",IF(N8=1,"✅ 100%",IF(L8=0,"Sin probar","En ciclo"))) | Q8: =COUNTIFS(Hallazgos!$B:$B,A8,Hallazgos!$M:$M,"<>Cerrado",Hallazgos!$A:$A,"<>") | R8: 9 bloques casi idénticos (parametrizable). El paso final 'El pedido debe quedar de la siguiente forma' remite a una imagen del archivo original.
A9: ESC-05 | B9: Seriado con cancelación de un día para que no deje forzar ese día de otro pedido | C9: Escenario 5 | D9: Pedidos / Asignaciones | E9: Validar seriados: bloque semanal, cancelación de un día y que no se pueda forzar ese día desde otro pedido según la propiedad del puesto. | F9: Requiere que un empleado confirme el bloque (portal) | G9: S05 | H9: 48 | I9: 43 | J9: 1 | K9: 4 | L9: ='ESC-05'!J3 | M9: ='ESC-05'!J4 | N9: ='ESC-05'!J5 | O9: =IF(H9=0,"Por definir",IF(N9=1,"✅ 100%",IF(L9=0,"Sin probar","En ciclo"))) | Q9: =COUNTIFS(Hallazgos!$B:$B,A9,Hallazgos!$M:$M,"<>Cerrado",Hallazgos!$A:$A,"<>") | R9: Numeración repetida (varios pasos '13'). Producto de Operaciones Inmuebles con esperado 'catálogo PRG'. Fase: legado observa 'Ninguno' vs 'No aplica'. Variante final sin pasos.
A10: ESC-06 | B10: Pedido de Transporte con empalme de horario | C10: Escenario 6 | D10: Pedidos | E10: Validar la detección de empalme de horarios entre detalles de un pedido de Transporte. | F10: — | G10: S06 | H10: 5 | I10: 2 | J10: 2 | K10: 1 | L10: ='ESC-06'!J3 | M10: ='ESC-06'!J4 | N10: ='ESC-06'!J5 | O10: =IF(H10=0,"Por definir",IF(N10=1,"✅ 100%",IF(L10=0,"Sin probar","En ciclo"))) | Q10: =COUNTIFS(Hallazgos!$B:$B,A10,Hallazgos!$M:$M,"<>Cerrado",Hallazgos!$A:$A,"<>")
A11: ESC-07 | B11: Comprobar fecha y hora de liberación | C11: Escenario 7 | D11: Pedidos | E11: Validar la liberación programada por fecha y hora, y la actualización del semáforo. | F11: Espera de 1 hora real | G11: S06 | H11: 5 | I11: 2 | J11: 0 | K11: 3 | L11: ='ESC-07'!J3 | M11: ='ESC-07'!J4 | N11: ='ESC-07'!J5 | O11: =IF(H11=0,"Por definir",IF(N11=1,"✅ 100%",IF(L11=0,"Sin probar","En ciclo"))) | Q11: =COUNTIFS(Hallazgos!$B:$B,A11,Hallazgos!$M:$M,"<>Cerrado",Hallazgos!$A:$A,"<>") | R11: Requiere esperar la hora programada; considerar mecanismo para simular tiempo.
A12: ESC-08 | B12: Validación de plazas | C12: Escenario 8 | D12: Asignaciones / Nómina | E12: Validar el sueldo según plaza vigente en la fecha del evento y su recálculo al mover la fecha de inicio. | F12: Empleado ID 54943; fechas 2019 | G12: S07 | H12: 13 | I12: 0 | J12: 0 | K12: 13 | L12: ='ESC-08'!J3 | M12: ='ESC-08'!J4 | N12: ='ESC-08'!J5 | O12: =IF(H12=0,"Por definir",IF(N12=1,"✅ 100%",IF(L12=0,"Sin probar","En ciclo"))) | Q12: =COUNTIFS(Hallazgos!$B:$B,A12,Hallazgos!$M:$M,"<>Cerrado",Hallazgos!$A:$A,"<>") | R12: Usa fechas de 2019: confirmar si siguen siendo válidas en el sistema nuevo.
A13: ESC-09 | B13: Validación de certeza valor | C13: Escenario 9 | D13: Asignaciones | E13: Validar que la certeza valor del empleado restringe visibilidad y asignación forzada. | F13: Empleado ID 57231 | G13: S07 | H13: 7 | I13: 0 | J13: 0 | K13: 7 | L13: ='ESC-09'!J3 | M13: ='ESC-09'!J4 | N13: ='ESC-09'!J5 | O13: =IF(H13=0,"Por definir",IF(N13=1,"✅ 100%",IF(L13=0,"Sin probar","En ciclo"))) | Q13: =COUNTIFS(Hallazgos!$B:$B,A13,Hallazgos!$M:$M,"<>Cerrado",Hallazgos!$A:$A,"<>")
A14: ESC-10 | B14: Cancelación de preasignación forzada por no confirmación | C14: Escenario 10 | D14: Asignaciones | E14: Validar el proceso de cancelación de preasignaciones no confirmadas y la visibilidad posterior. | F14: Empleados ID 3891, 16338, 33817, 46486, 54501 | G14: S08 | H14: 7 | I14: 1 | J14: 0 | K14: 6 | L14: ='ESC-10'!J3 | M14: ='ESC-10'!J4 | N14: ='ESC-10'!J5 | O14: =IF(H14=0,"Por definir",IF(N14=1,"✅ 100%",IF(L14=0,"Sin probar","En ciclo"))) | Q14: =COUNTIFS(Hallazgos!$B:$B,A14,Hallazgos!$M:$M,"<>Cerrado",Hallazgos!$A:$A,"<>") | R14: Pide 4 personas pero lista 5 IDs.
A15: ESC-11 | B15: Confirmación de personal sin puesto asignado vigente | C15: Escenario 11 | D15: Asignaciones | E15: Validar que no se permita preasignar a un empleado sin puesto vigente. | F15: Empleado ID 58172 | G15: S07 | H15: 7 | I15: 5 | J15: 0 | K15: 2 | L15: ='ESC-11'!J3 | M15: ='ESC-11'!J4 | N15: ='ESC-11'!J5 | O15: =IF(H15=0,"Por definir",IF(N15=1,"✅ 100%",IF(L15=0,"Sin probar","En ciclo"))) | Q15: =COUNTIFS(Hallazgos!$B:$B,A15,Hallazgos!$M:$M,"<>Cerrado",Hallazgos!$A:$A,"<>") | R15: Legado: los mensajes emergentes no indican qué regla falló.
A16: ESC-12 | B16: Productos similares | C16: Escenario 12 | D16: Asignaciones | E16: Validar la regla de productos similares en asignación y visibilidad. | F16: Al menos un empleado de control de accesos | G16: S08 | H16: 13 | I16: 5 | J16: 0 | K16: 8 | L16: ='ESC-12'!J3 | M16: ='ESC-12'!J4 | N16: ='ESC-12'!J5 | O16: =IF(H16=0,"Por definir",IF(N16=1,"✅ 100%",IF(L16=0,"Sin probar","En ciclo"))) | Q16: =COUNTIFS(Hallazgos!$B:$B,A16,Hallazgos!$M:$M,"<>Cerrado",Hallazgos!$A:$A,"<>")
A17: ESC-13 | B17: Validar que no se puedan cancelar reservaciones | C17: Escenario 13 | D17: Asignaciones | E17: Validar las reglas de cancelación de confirmaciones: pedido/detalle, 72 horas y cambio de horario con aviso. | F17: Varios empleados de seguridad con acceso al portal | G17: S09 | H17: 29 | I17: 0 | J17: 0 | K17: 29 | L17: ='ESC-13'!J3 | M17: ='ESC-13'!J4 | N17: ='ESC-13'!J5 | O17: =IF(H17=0,"Por definir",IF(N17=1,"✅ 100%",IF(L17=0,"Sin probar","En ciclo"))) | Q17: =COUNTIFS(Hallazgos!$B:$B,A17,Hallazgos!$M:$M,"<>Cerrado",Hallazgos!$A:$A,"<>") | R17: Nota: se repetirá cambiando lugar de cita y turnos.
A18: ESC-14 | B18: Pedido de matriciales para validar los sueldos | C18: Escenario 14 | D18: Nómina | E18: Validar el sueldo matricial en el portal del empleado (Saldos / eventos por procesar). | F18: Empleado con puesto Asistente Operador - IN | G18: S12 | H18: 10 | I18: 5 | J18: 0 | K18: 5 | L18: ='ESC-14'!J3 | M18: ='ESC-14'!J4 | N18: ='ESC-14'!J5 | O18: =IF(H18=0,"Por definir",IF(N18=1,"✅ 100%",IF(L18=0,"Sin probar","En ciclo"))) | Q18: =COUNTIFS(Hallazgos!$B:$B,A18,Hallazgos!$M:$M,"<>Cerrado",Hallazgos!$A:$A,"<>")
A19: ESC-15 | B19: Cancelación de asignación forzada | C19: Escenario 15 | D19: Asignaciones | E19: Validar que el empleado no pueda cancelar una asignación forzada. | F19: — | G19: S08 | H19: 8 | I19: 0 | J19: 0 | K19: 8 | L19: ='ESC-15'!J3 | M19: ='ESC-15'!J4 | N19: ='ESC-15'!J5 | O19: =IF(H19=0,"Por definir",IF(N19=1,"✅ 100%",IF(L19=0,"Sin probar","En ciclo"))) | Q19: =COUNTIFS(Hallazgos!$B:$B,A19,Hallazgos!$M:$M,"<>Cerrado",Hallazgos!$A:$A,"<>")
A20: ESC-16 | B20: Disminución de personal solicitado + Certeza valor | C20: Escenario 16 | D20: Asignaciones | E20: Validar que al reducir personal se cancelen primero los de menor certeza valor y luego el último confirmado. | F20: Empleados ID 1, 1962, 2074, 2116, 2790, 2795 | G20: S10 | H20: 17 | I20: 7 | J20: 0 | K20: 10 | L20: ='ESC-16'!J3 | M20: ='ESC-16'!J4 | N20: ='ESC-16'!J5 | O20: =IF(H20=0,"Por definir",IF(N20=1,"✅ 100%",IF(L20=0,"Sin probar","En ciclo"))) | Q20: =COUNTIFS(Hallazgos!$B:$B,A20,Hallazgos!$M:$M,"<>Cerrado",Hallazgos!$A:$A,"<>")
A21: ESC-17A | B21: Prorrateo (PENDIENTE TIGRE) | C21: Escenario 17 (numeración duplicada) | D21: Nómina | E21: Prorrateo (pendiente TIGRE). | F21: — | G21: S12 | H21: 10 | I21: 0 | J21: 0 | K21: 10 | L21: ='ESC-17A'!J3 | M21: ='ESC-17A'!J4 | N21: ='ESC-17A'!J5 | O21: =IF(H21=0,"Por definir",IF(N21=1,"✅ 100%",IF(L21=0,"Sin probar","En ciclo"))) | Q21: =COUNTIFS(Hallazgos!$B:$B,A21,Hallazgos!$M:$M,"<>Cerrado",Hallazgos!$A:$A,"<>") | R21: Contenido idéntico a ESC-14. Confirmar si es duplicado o falta definir los pasos.
A22: ESC-17B | B22: Pedido con 0.25 Turnos | C22: Escenario 17 (numeración duplicada) | D22: Pedidos / Nómina | E22: Validar turnos fraccionados (0.25): costo de nómina y fecha fin calculada. | F22: — | G22: S06 | H22: 7 | I22: 5 | J22: 2 | K22: 0 | L22: ='ESC-17B'!J3 | M22: ='ESC-17B'!J4 | N22: ='ESC-17B'!J5 | O22: =IF(H22=0,"Por definir",IF(N22=1,"✅ 100%",IF(L22=0,"Sin probar","En ciclo"))) | Q22: =COUNTIFS(Hallazgos!$B:$B,A22,Hallazgos!$M:$M,"<>Cerrado",Hallazgos!$A:$A,"<>")
A23: ESC-18 | B23: Lista Negra | C23: Escenario 18 | D23: Asignaciones / Seguridad | E23: Validar la lista negra: permisos de administración y bloqueo del empleado vetado por inmueble. | F23: Usuario con accesos (Arturo Pérez) | G23: S10 | H23: 14 | I23: 0 | J23: 0 | K23: 14 | L23: ='ESC-18'!J3 | M23: ='ESC-18'!J4 | N23: ='ESC-18'!J5 | O23: =IF(H23=0,"Por definir",IF(N23=1,"✅ 100%",IF(L23=0,"Sin probar","En ciclo"))) | Q23: =COUNTIFS(Hallazgos!$B:$B,A23,Hallazgos!$M:$M,"<>Cerrado",Hallazgos!$A:$A,"<>")
A24: ESC-19 | B24: Crear pedidos de fechas pasadas | C24: Escenario 19 | D24: Pedidos / Asignaciones | E24: Validar pedidos con fechas pasadas y el bloqueo por conflicto de asignación. | F24: — | G24: S06 | H24: 10 | I24: 4 | J24: 6 | K24: 0 | L24: ='ESC-19'!J3 | M24: ='ESC-19'!J4 | N24: ='ESC-19'!J5 | O24: =IF(H24=0,"Por definir",IF(N24=1,"✅ 100%",IF(L24=0,"Sin probar","En ciclo"))) | Q24: =COUNTIFS(Hallazgos!$B:$B,A24,Hallazgos!$M:$M,"<>Cerrado",Hallazgos!$A:$A,"<>")
A25: ESC-20 | B25: Relación de contacto-cliente | C25: Escenario 20 | D25: Pedidos | E25: Validar el alta de contactos y su relación con el cliente. | F25: Usuario de Axel | G25: S06 | H25: 8 | I25: 0 | J25: 0 | K25: 8 | L25: ='ESC-20'!J3 | M25: ='ESC-20'!J4 | N25: ='ESC-20'!J5 | O25: =IF(H25=0,"Por definir",IF(N25=1,"✅ 100%",IF(L25=0,"Sin probar","En ciclo"))) | Q25: =COUNTIFS(Hallazgos!$B:$B,A25,Hallazgos!$M:$M,"<>Cerrado",Hallazgos!$A:$A,"<>")
A26: ESC-21 | B26: Validar funcionalidad pantalla interna de reservaciones (Igual a la actual) | C26: Escenario 21 | D26: Reservaciones | E26: Validar la pantalla interna de reservaciones con paridad funcional respecto al legado. | F26: — | G26: S11 | H26: 22 | I26: 0 | J26: 0 | K26: 22 | L26: ='ESC-21'!J3 | M26: ='ESC-21'!J4 | N26: ='ESC-21'!J5 | O26: =IF(H26=0,"Por definir",IF(N26=1,"✅ 100%",IF(L26=0,"Sin probar","En ciclo"))) | Q26: =COUNTIFS(Hallazgos!$B:$B,A26,Hallazgos!$M:$M,"<>Cerrado",Hallazgos!$A:$A,"<>") | R26: El árbol esperado está como imagen en el archivo original.
A27: ESC-22 | B27: Captura de lista manual de asistencia | C27: Escenario 22 | D27: Nómina | E27: Validar la lista manual de asistencia y el cálculo de pagos honorarios (asistencia, falta, retardo) con valores exactos. | F27: Pedido pasado con 10 empleados asignados (forzada) | G27: S13 | H27: 67 | I27: 2 | J27: 0 | K27: 65 | L27: ='ESC-22'!J3 | M27: ='ESC-22'!J4 | N27: ='ESC-22'!J5 | O27: =IF(H27=0,"Por definir",IF(N27=1,"✅ 100%",IF(L27=0,"Sin probar","En ciclo"))) | Q27: =COUNTIFS(Hallazgos!$B:$B,A27,Hallazgos!$M:$M,"<>Cerrado",Hallazgos!$A:$A,"<>") | R27: Combinaciones con 'Penalización Retardo/Falta' mencionadas pero sin pasos.
A28: ESC-23 | B28: Extras | C28: Escenario 23 | D28: Nómina | E28: Validar extras: captura, autorización por perfil, aprobación masiva e impacto en el pago. | F28: ESC-22 | G28: S13 | H28: 17 | I28: 0 | J28: 0 | K28: 17 | L28: ='ESC-23'!J3 | M28: ='ESC-23'!J4 | N28: ='ESC-23'!J5 | O28: =IF(H28=0,"Por definir",IF(N28=1,"✅ 100%",IF(L28=0,"Sin probar","En ciclo"))) | Q28: =COUNTIFS(Hallazgos!$B:$B,A28,Hallazgos!$M:$M,"<>Cerrado",Hallazgos!$A:$A,"<>")
A29: ESC-24 | B29: Dispersión de nómina y Lista de Precauciones | C29: Escenario 24 | D29: Nómina | E29: Validar el cierre de nómina: lista de precauciones y archivo de dispersión. | F29: ESC-22, ESC-23 | G29: S13 | H29: 10 | I29: 0 | J29: 0 | K29: 10 | L29: ='ESC-24'!J3 | M29: ='ESC-24'!J4 | N29: ='ESC-24'!J5 | O29: =IF(H29=0,"Por definir",IF(N29=1,"✅ 100%",IF(L29=0,"Sin probar","En ciclo"))) | Q29: =COUNTIFS(Hallazgos!$B:$B,A29,Hallazgos!$M:$M,"<>Cerrado",Hallazgos!$A:$A,"<>")
A30: ESC-25 | B30: Asignación de folio para empleados con Honorarios Normales | C30: Escenario 25 | D30: Nómina | E30: Validar la asignación de folio fiscal para honorarios normales y su efecto en el importe. | F30: — | G30: S14 | H30: 17 | I30: 0 | J30: 0 | K30: 17 | L30: ='ESC-25'!J3 | M30: ='ESC-25'!J4 | N30: ='ESC-25'!J5 | O30: =IF(H30=0,"Por definir",IF(N30=1,"✅ 100%",IF(L30=0,"Sin probar","En ciclo"))) | Q30: =COUNTIFS(Hallazgos!$B:$B,A30,Hallazgos!$M:$M,"<>Cerrado",Hallazgos!$A:$A,"<>")
A31: ESC-26 | B31: Pedidos de runners para validar los sueldos | C31: Escenario 26 | D31: Nómina | E31: Validar el sueldo de runners por fase y sus impuestos (IVA, RIVA, RISR). | F31: — | G31: S14 | H31: 34 | I31: 0 | J31: 0 | K31: 34 | L31: ='ESC-26'!J3 | M31: ='ESC-26'!J4 | N31: ='ESC-26'!J5 | O31: =IF(H31=0,"Por definir",IF(N31=1,"✅ 100%",IF(L31=0,"Sin probar","En ciclo"))) | Q31: =COUNTIFS(Hallazgos!$B:$B,A31,Hallazgos!$M:$M,"<>Cerrado",Hallazgos!$A:$A,"<>")
A32: ESC-27 | B32: Facturación | C32: Escenario 28 (numeración duplicada) | D32: Facturación | E32: Validar la generación de facturas: folios, partidas, agrupación de rubros y txt a SAP. | F32: ESC-22 | G32: S15 | H32: 16 | I32: 0 | J32: 0 | K32: 16 | L32: ='ESC-27'!J3 | M32: ='ESC-27'!J4 | N32: ='ESC-27'!J5 | O32: =IF(H32=0,"Por definir",IF(N32=1,"✅ 100%",IF(L32=0,"Sin probar","En ciclo"))) | Q32: =COUNTIFS(Hallazgos!$B:$B,A32,Hallazgos!$M:$M,"<>Cerrado",Hallazgos!$A:$A,"<>") | R32: La lista de campos del paso 6 está como imagen en el archivo original.
A33: ESC-28 | B33: Validar que en el txt sólo se generan facturas (Y no servicios internos) | C33: Escenario 28 (numeración duplicada) | D33: Facturación | E33: Validar que los servicios internos no generan txt ni consumen folio consecutivo. | F33: ESC-26 | G33: S15 | H33: 5 | I33: 0 | J33: 0 | K33: 5 | L33: ='ESC-28'!J3 | M33: ='ESC-28'!J4 | N33: ='ESC-28'!J5 | O33: =IF(H33=0,"Por definir",IF(N33=1,"✅ 100%",IF(L33=0,"Sin probar","En ciclo"))) | Q33: =COUNTIFS(Hallazgos!$B:$B,A33,Hallazgos!$M:$M,"<>Cerrado",Hallazgos!$A:$A,"<>")
A34: ESC-29 | B34: Prorrateo de sueldos matriciales | C34: Escenario 29 | D34: Nómina | E34: Validar el prorrateo de sueldo matricial entre varios detalles (100-50-50 repartido). | F34: — | G34: S12 | H34: 8 | I34: 0 | J34: 0 | K34: 8 | L34: ='ESC-29'!J3 | M34: ='ESC-29'!J4 | N34: ='ESC-29'!J5 | O34: =IF(H34=0,"Por definir",IF(N34=1,"✅ 100%",IF(L34=0,"Sin probar","En ciclo"))) | Q34: =COUNTIFS(Hallazgos!$B:$B,A34,Hallazgos!$M:$M,"<>Cerrado",Hallazgos!$A:$A,"<>")
A35: ESC-30 | B35: Validación de Visibilidad por sucursal/puesto | C35: — (nota al pie) | D35: Reservaciones | E35: Validación de visibilidad por sucursal/puesto. | F35: — | G35: S11 | H35: 0 | I35: 0 | J35: 0 | K35: 0 | L35: ='ESC-30'!J3 | M35: ='ESC-30'!J4 | N35: ='ESC-30'!J5 | O35: =IF(H35=0,"Por definir",IF(N35=1,"✅ 100%",IF(L35=0,"Sin probar","En ciclo"))) | Q35: =COUNTIFS(Hallazgos!$B:$B,A35,Hallazgos!$M:$M,"<>Cerrado",Hallazgos!$A:$A,"<>") | R35: Sin pasos en el archivo original.
A36: ESC-31 | B36: Justificación de Faltas (Validar que el porcentaje de asistencia se modifica) | C36: — (nota al pie) | D36: Nómina | E36: Justificación de faltas (validar que el porcentaje de asistencia se modifica). | F36: — | G36: S13 | H36: 0 | I36: 0 | J36: 0 | K36: 0 | L36: ='ESC-31'!J3 | M36: ='ESC-31'!J4 | N36: ='ESC-31'!J5 | O36: =IF(H36=0,"Por definir",IF(N36=1,"✅ 100%",IF(L36=0,"Sin probar","En ciclo"))) | Q36: =COUNTIFS(Hallazgos!$B:$B,A36,Hallazgos!$M:$M,"<>Cerrado",Hallazgos!$A:$A,"<>") | R36: Sin pasos en el archivo original.
A38: TOTAL | H38: =SUM(H5:H36) | I38: =SUM(I5:I36) | J38: =SUM(J5:J36) | K38: =SUM(K5:K36) | L38: =SUM(L5:L36) | M38: =SUM(M5:M36) | N38: =IF(H38=0,0,M38/H38) | Q38: =SUM(Q5:Q36)

Sheet Sesiones
A1: Sesiones de Claude Code — cada sesión cubre un escenario o un grupo que comparte datos
A3: Sesión | B3: Escenarios | C3: Tema | D3: Pasos | E3: Por qué juntos
A4: S01 | B4: ESC-01 | C4: Pedido Seguridad básico | D4: 25 | E4: Base de todos los escenarios de pedidos.
A5: S02 | B5: ESC-02 | C5: PRG con complejidad | D5: 26 | E5: Staff, bloques y presupuesto.
A6: S03 | B6: ESC-03 | C6: PRG por fases | D6: 32 | E6: Múltiples detalles por fase.
A7: S04 | B7: ESC-04 | C7: Pedido masivo Azteca | D7: 106 | E7: Volumen; buen candidato a parametrizar.
A8: S05 | B8: ESC-05 | C8: Seriados | D8: 48 | E8: Requiere confirmación de bloque en portal.
A9: S06 | B9: ESC-06, ESC-07, ESC-17B, ESC-19, ESC-20 | C9: Reglas de pedido | D9: 35 | E9: Escenarios cortos e independientes del módulo de pedidos.
A10: S07 | B10: ESC-08, ESC-09, ESC-11 | C10: Elegibilidad del empleado | D10: 27 | E10: Plaza, certeza valor y puesto vigente.
A11: S08 | B11: ESC-10, ESC-12, ESC-15 | C11: Asignación y preasignación | D11: 28 | E11: Reglas de asignación forzada y preasignada.
A12: S09 | B12: ESC-13 | C12: Cancelaciones | D12: 29 | E12: Escenario largo con varios empleados en portal.
A13: S10 | B13: ESC-16, ESC-18 | C13: Restricciones de asignación | D13: 31 | E13: Certeza en reducción y lista negra.
A14: S11 | B14: ESC-21, ESC-30 | C14: Reservaciones internas | D14: 22 | E14: Paridad con legado y visibilidad.
A15: S12 | B15: ESC-14, ESC-17A, ESC-29 | C15: Sueldos matriciales | D15: 28 | E15: Mismo cálculo de complejidad y prorrateo.
... A18: S15 | B18: ESC-27, ESC-28 | C18: Facturación | D18: 21 | E18: Dependen de ESC-22 y ESC-26.

Sheet Hallazgos
A1: ID | B1: Escenario | C1: Paso # | D1: Corrida detectado | E1: Clasificación | F1: Severidad | G1: Descripción | H1: Evidencia | I1: Causa raíz | J1: Decisión negocio | K1: Corregido (commit) | L1: Verificado en corrida | M1: Estado
A2: H-001 | B2: ESC-01 | C2: 3 | D2: R1 | E2: BUG | F2: Media | G2: Ejemplo — Contacto vacío en la ficha del pedido | H2: corridas/R1/evidencias/ESC-01/P10_despues.png | I2: Ficha lee contacto_nombre; el formulario guarda contacto_id | J2: N/A | K2: abc1234 | L2: R2 | M2: Cerrado
A3: H-002 | B3: ESC-02 | C3: 7-8 | D3: R1 | E3: CAMBIO_NOMENCLATURA | G3: "Tipo de movimiento" real tiene 3 valores (Orden de servicio / Pedido facturable a cliente / Servicio interno); el caso esperaba 2 ("Pedido"/"Servicio Interno") y un campo "Facturable" editable separado que no existe (va embebido en el texto de la opcion). | H3: Tests/corridas/2026-10-10_R1_ESC-02/bitacora.jsonl (pasos 7-8); resumen_ejecucion.md | I3: Nomenclatura de catalogo/UI, no es un defecto de codigo. | J3: Pendiente | M3: Abierto
A4: H-003 | B4: ESC-02 | C4: 13-14 | D4: R1 | E4: CAMBIO_NOMENCLATURA | G4: tc_tipos_personal no usa los textos "Staff"/"Operativo". Usa clave freelance/interno/staff con descripciones "Personal freelance / eventual" / "Personal interno de oficina" / "Personal de planta". La clave staff SI implementa correctamente el gating de negocio (Staff solo visible si el pedido tiene complejidad) -- verificado releyendo codigo y reprobando en vivo tras un primer intento con sustituto incorrecto. | H4: Tests/corridas/2026-10-10_R1_ESC-02/bitacora.jsonl (pasos 13-14); verificacion directa del combo | I4: Nomenclatura de catalogo (tc_tipos_personal.descripcion), no de codigo. | J4: Pendiente: evaluar renombrar descripciones a "Staff"/"Operativo"/"Interno" | M4: Abierto
A5: H-004 | B5: ESC-02 | C5: 13 | D5: R1 | E5: BUG | F5: Baja | G5: tc_tipos_personal tiene 9 filas para solo 3 claves reales (freelance/interno/staff cada una triplicada con IDs distintos). La UI de alta de detalle solo mostro 3 opciones visibles en esta prueba; de cualquier forma la tabla en BD tiene filas redundantes. | H5: Consulta SQL directa a tc_tipos_personal (9 filas, 3 claves) | I5: Dato duplicado en seed/migracion; causa raiz en codigo no investigada (fuera de alcance de esta sesion). | J5: Pendiente: aprobar limpieza (dejar 1 fila por clave) | M5: Abierto
A6: H-005 | B6: ESC-02 | C6: 15-26 | D6: R1 | E6: GAP_MIGRACION | F6: Alta | G6: Ningun puesto matricial de la UN PRG tiene fila en tp_sueldos_matriciales (0 de 6 puestos PRG preexistentes, y tampoco los 2 insertados para esta prueba -- Asistente Operador PRG y Asistente Aux A PRG). Esto deja VACIO el combo de Producto al elegir Tipo de Personal=Staff para cualquier pedido de PRG, bloqueando el alta de todo el bloque de personal Staff de esa unidad de negocio. | H6: SQL (0 filas); capturas del combo vacio; Tests/corridas/2026-10-10_R1_ESC-02/bitacora.jsonl | I6: Migracion de datos incompleta: el legado real (Ocesa03_j_m.accdb) tiene 171 productos reales de PRG y puestos matriciales confirmados, pero el archivo fuente de tarifas (Catalogos Sueldos Matriciales.xlsx, citado en CLAUDE.md migraciones 022/031) no esta presente en este repo para poder sembrar tarifas reales. | J6: Pendiente: conseguir/aprobar fuente real de tarifas matriciales de PRG para poder sembrar tp_sueldos_matriciales | M6: Abierto
A7: H-006 | B7: ESC-02 | C7: colateral | D7: R1 | E7: BUG | F7: Media | G7: Las pantallas "Pedidos y sitios" y "Arbol de reservaciones" no muestran pedidos con fecha_evento antigua (confirmado invisible: pedido #199, fecha_evento=2018-09-01) pese a existir en BD -- aparente corte/limite de carga sin paginacion (se corta alrededor de 2018-09-21 hacia atras, aunque la BD tiene 199+ pedidos). | H7: Tests/corridas/2026-10-10_R1_ESC-02/bitacora.jsonl (paso 0, intentos 1-2); prueba de control con folio 36 (si se encontro) | I7: No investigada en codigo (fuera de alcance de esta sesion de QA). | J7: Pendiente: priorizar investigacion / agregar paginacion a la lista | M7: Abierto

Sheet Instrucciones
A1: CICLO POR SESIÓN
A2: 1. Probar (R1) | B2: qa-tester ejecuta los escenarios de la sesión y llena 'R1 Resultado' y 'R1 Hallazgo / Obs.' con evidencia.
A3: 2. Analizar | B3: qa-analista registra cada resultado distinto de CUMPLE en 'Hallazgos' con ID H-xxx y lo referencia en la columna de observación.
A4: 3. Decidir | B4: Negocio resuelve DISCREPANCIA_NEGOCIO, CAMBIO_NOMENCLATURA y CASO_AMBIGUO en la columna 'Decisión negocio'.
A5: 4. Corregir | B5: qa-corrector corrige solo hallazgos 'Aprobado corregir', un commit por hallazgo; estado → 'Por verificar'.
A6: 5. Re-probar (R2, R3…) | B6: Se re-ejecuta el escenario completo en la siguiente columna Rn. Hallazgos verificados → 'Cerrado'.
A7: 6. Cerrar | B7: El escenario se cierra cuando Control muestra '✅ 100%' y no tiene hallazgos abiertos.
A9: RESULTADO
A10: CUMPLE | B10: Coincide con el esperado, con evidencia.
A11: NO CUMPLE | B11: No coincide con el esperado.
A12: PARCIAL | B12: Existe la funcionalidad pero el dato o comportamiento difiere.
A13: NO EJECUTABLE | B13: No se puede probar (datos, catálogo, precondición).
A14: VERIFICAR | B14: Ejecutado sin evidencia o con juicio a confirmar.
A15: PENDIENTE | B15: No ejecutado.
A17: COMPARATIVO (calculado)
A18: Mejora / Mejora parcial | B18: Fallaba en legado y ahora cumple (total o parcialmente).
A19: Regresión | B19: Cumplía en legado y ahora falla.
A20: Falla nueva | B20: No se ejecutó en legado y falla ahora.
A21: Sigue fallando | B21: Fallaba en legado y sigue fallando.
A22: Se mantiene | B22: Mismo resultado que en legado.
A24: COLORES
A25: Gris | B25: Datos del legado: no editar.
A26: Azul | B26: Columnas del ciclo Claude Code: editables.
A27: Naranja | B27: Problema de calidad del caso: resolver antes de ejecutar ese paso.
A28: Negritas | B28: Fórmulas (Último resultado, Comparativo, resúmenes): no editar.
A30: REGLA | B30: Nunca se edita la descripción ni el resultado esperado. Si negocio cambia un esperado, se anota en Hallazgos como CASO_AMBIGUO con la decisión.

Sheet ESC-01
A1: ESC-01 — Pedido para Metropólitan (Seguridad) - Sin Cancelación
A2: Núm. original | B2: Escenario 1 | I2: Pasos | J2: =COUNT(A13:A38)
A3: Módulo | B3: Pedidos | I3: Ejecutados (último) | J3: =COUNTIF(O13:O38,"?*")
A4: Objetivo (propuesto, validar) | B4: Validar el alta completa de un pedido de Seguridad sin cancelación y su detalle, hasta la cancelación del pedido. | I4: CUMPLE (último) | J4: =COUNTIF(O13:O38,"CUMPLE")
A5: Funcionalidades | B5: Alta de pedido · contactos por cliente · PEP y sociedad pagadora · tipo de movimiento · estatus · catálogo por UN · jornada por turno · validación de fechas · matriz · acciones del detalle · cancelación | I5: % cumplimiento | J5: =IF(J2=0,0,J4/J2)
A6: Dependencias / datos | B6: —
A7: Sesión sugerida | B7: S01
A8: ⚠ Calidad del caso | B8: Paso 13: la descripción (prerellenos) y el esperado (productos de Seguridad) no corresponden.
A9: Notas originales | B9: —
F11: CORRIDA LEGADO (HUMANOS) | I11: CICLO CLAUDE CODE: probar → corregir → re-probar
A12: # | B12: Paso orig. | C12: Descripción | D12: Resultado esperado | E12: ⚠ Calidad | F12: Legado: Resultado | G12: Legado: Observación | H12: Legado: Corrección | I12: R1 Resultado | J12: R1 Hallazgo / Obs. | K12: R2 Resultado | L12: R2 Hallazgo / Obs. | M12: R3 Resultado | N12: R3 Hallazgo / Obs. | O12: Último resultado | P12: Comparativo
A13: 1 | B13: 1 | C13: Crear un nuevo pedido | F13: Cumple | O13: =IF(M13<>"",M13,IF(K13<>"",K13,IF(I13<>"",I13,""))) | P13: =IF(O13="","",IF(O13="PENDIENTE","Pendiente",IF(O13="NO EJECUTABLE","No ejecutable",IF(O13="VERIFICAR","Por verificar",IF(AND(F13="No cumple",O13="CUMPLE"),"Mejora",IF(AND(F13="No cumple",O13="PARCIAL"),"Mejora parcial",IF(AND(OR(F13="Cumple",F13="Sin ejecutar"),OR(O13="NO CUMPLE",O13="PARCIAL")),IF(F13="Cumple","Regresión","Falla nueva"),IF(AND(F13="No cumple",O13="NO CUMPLE"),"Sigue fallando","Se mantiene"))))))))
A14: 2 | B14: 2 | C14: Seleccionar cliente Ocesa | F14: Cumple | O14: =IF(M14<>"",M14,IF(K14<>"",K14,IF(I14<>"",I14,""))) | P14: =IF(O14="","",IF(O14="PENDIENTE","Pendiente",IF(O14="NO EJECUTABLE","No ejecutable",IF(O14="VERIFICAR","Por verificar",IF(AND(F14="No cumple",O14="CUMPLE"),"Mejora",IF(AND(F14="No cumple",O14="PARCIAL"),"Mejora parcial",IF(AND(OR(F14="Cumple",F14="Sin ejecutar"),OR(O14="NO CUMPLE",O14="PARCIAL")),IF(F14="Cumple","Regresión","Falla nueva"),IF(AND(F14="No cumple",O14="NO CUMPLE"),"Sigue fallando","Se mantiene"))))))))
A15: 3 | B15: 3 | C15: Validar lista de contactos | D15: Los contactos mostrados deben pertenecer al cliente Ocesa | F15: Cumple | O15: =IF(M15<>"",M15,IF(K15<>"",K15,IF(I15<>"",I15,""))) | P15: =IF(O15="","",IF(O15="PENDIENTE","Pendiente",IF(O15="NO EJECUTABLE","No ejecutable",IF(O15="VERIFICAR","Por verificar",IF(AND(F15="No cumple",O15="CUMPLE"),"Mejora",IF(AND(F15="No cumple",O15="PARCIAL"),"Mejora parcial",IF(AND(OR(F15="Cumple",F15="Sin ejecutar"),OR(O15="NO CUMPLE",O15="PARCIAL")),IF(F15="Cumple","Regresión","Falla nueva"),IF(AND(F15="No cumple",O15="NO CUMPLE"),"Sigue fallando","Se mantiene"))))))))
A16: 4 | B16: 4 | C16: Seleccionar un evento | F16: Cumple | O16: =IF(M16<>"",M16,IF(K16<>"",K16,IF(I16<>"",I16,""))) | P16: =IF(O16="","",IF(O16="PENDIENTE","Pendiente",IF(O16="NO EJECUTABLE","No ejecutable",IF(O16="VERIFICAR","Por verificar",IF(AND(F16="No cumple",O16="CUMPLE"),"Mejora",IF(AND(F16="No cumple",O16="PARCIAL"),"Mejora parcial",IF(AND(OR(F16="Cumple",F16="Sin ejecutar"),OR(O16="NO CUMPLE",O16="PARCIAL")),IF(F16="Cumple","Regresión","Falla nueva"),IF(AND(F16="No cumple",O16="NO CUMPLE"),"Sigue fallando","Se mantiene"))))))))
A17: 5 | B17: 5 | C17: Seleccionar UN Seguridad | D17: El sistema despliega los PEPS de la UN de seguridad, y la sociedad pagadora (en este caso Lobo) | F17: No cumple | G17: Antes de seleccionar la UN la sociedad pagadora está por default con ID 10 | H17: Corregido | O17: =IF(M17<>"",M17,IF(K17<>"",K17,IF(I17<>"",I17,""))) | P17: =IF(O17="","",IF(O17="PENDIENTE","Pendiente",IF(O17="NO EJECUTABLE","No ejecutable",IF(O17="VERIFICAR","Por verificar",IF(AND(F17="No cumple",O17="CUMPLE"),"Mejora",IF(AND(F17="No cumple",O17="PARCIAL"),"Mejora parcial",IF(AND(OR(F17="Cumple",F17="Sin ejecutar"),OR(O17="NO CUMPLE",O17="PARCIAL")),IF(F17="Cumple","Regresión","Falla nueva"),IF(AND(F17="No cumple",O17="NO CUMPLE"),"Sigue fallando","Se mantiene"))))))))
A18: 6 | B18: 6 | C18: Seleccionar el PEPS asociado a la UN | D18: El sistema me muestra el nombre y la dirección del inmueble | F18: Cumple | O18: =IF(M18<>"",M18,IF(K18<>"",K18,IF(I18<>"",I18,""))) | P18: =IF(O18="","",IF(O18="PENDIENTE","Pendiente",IF(O18="NO EJECUTABLE","No ejecutable",IF(O18="VERIFICAR","Por verificar",IF(AND(F18="No cumple",O18="CUMPLE"),"Mejora",IF(AND(F18="No cumple",O18="PARCIAL"),"Mejora parcial",IF(AND(OR(F18="Cumple",F18="Sin ejecutar"),OR(O18="NO CUMPLE",O18="PARCIAL")),IF(F18="Cumple","Regresión","Falla nueva"),IF(AND(F18="No cumple",O18="NO CUMPLE"),"Sigue fallando","Se mantiene"))))))))
A19: 7 | B19: 7 | C19: Validar tipo de movimiento | D19: El sistema debe mostrar dos tipos de movimiento (Pedido y Servicio Interno) | F19: No cumple | G19: Únicamnete muestra "pedido" | H19: Corregido / Listo | O19: =IF(M19<>"",M19,IF(K19<>"",K19,IF(I19<>"",I19,""))) | P19: =IF(O19="","",IF(O19="PENDIENTE","Pendiente",IF(O19="NO EJECUTABLE","No ejecutable",IF(O19="VERIFICAR","Por verificar",IF(AND(F19="No cumple",O19="CUMPLE"),"Mejora",IF(AND(F19="No cumple",O19="PARCIAL"),"Mejora parcial",IF(AND(OR(F19="Cumple",F19="Sin ejecutar"),OR(O19="NO CUMPLE",O19="PARCIAL")),IF(F19="Cumple","Regresión","Falla nueva"),IF(AND(F19="No cumple",O19="NO CUMPLE"),"Sigue fallando","Se mantiene"))))))))
A20: 8 | B20: 8 | C20: Seleccionar Tipo de movimiento Pedido | D20: EL tipo Pedido se factura (validar posteriormente) | F20: Cumple | O20: =IF(M20<>"",M20,IF(K20<>"",K20,IF(I20<>"",I20,""))) | P20: =IF(O20="","",IF(O20="PENDIENTE","Pendiente",IF(O20="NO EJECUTABLE","No ejecutable",IF(O20="VERIFICAR","Por verificar",IF(AND(F20="No cumple",O20="CUMPLE"),"Mejora",IF(AND(F20="No cumple",O20="PARCIAL"),"Mejora parcial",IF(AND(OR(F20="Cumple",F20="Sin ejecutar"),OR(O20="NO CUMPLE",O20="PARCIAL")),IF(F20="Cumple","Regresión","Falla nueva"),IF(AND(F20="No cumple",O20="NO CUMPLE"),"Sigue fallando","Se mantiene"))))))))
A21: 9 | B21: 9 | C21: En el campo Permitir Cancelar, seleccionar NO | F21: Cumple | O21: =IF(M21<>"",M21,IF(K21<>"",K21,IF(I21<>"",I21,""))) | P21: =IF(O21="","",IF(O21="PENDIENTE","Pendiente",IF(O21="NO EJECUTABLE","No ejecutable",IF(O21="VERIFICAR","Por verificar",IF(AND(F21="No cumple",O21="CUMPLE"),"Mejora",IF(AND(F21="No cumple",O21="PARCIAL"),"Mejora parcial",IF(AND(OR(F21="Cumple",F21="Sin ejecutar"),OR(O21="NO CUMPLE",O21="PARCIAL")),IF(F21="Cumple","Regresión","Falla nueva"),IF(AND(F21="No cumple",O21="NO CUMPLE"),"Sigue fallando","Se mantiene"))))))))
A22: 10 | B22: 10 | C22: Pulsar Aceptar | D22: El sistema genera un número consecutivo de pedido. | F22: Cumple | O22: =IF(M22<>"",M22,IF(K22<>"",K22,IF(I22<>"",I22,""))) | P22: =IF(O22="","",IF(O22="PENDIENTE","Pendiente",IF(O22="NO EJECUTABLE","No ejecutable",IF(O22="VERIFICAR","Por verificar",IF(AND(F22="No cumple",O22="CUMPLE"),"Mejora",IF(AND(F22="No cumple",O22="PARCIAL"),"Mejora parcial",IF(AND(OR(F22="Cumple",F22="Sin ejecutar"),OR(O22="NO CUMPLE",O22="PARCIAL")),IF(F22="Cumple","Regresión","Falla nueva"),IF(AND(F22="No cumple",O22="NO CUMPLE"),"Sigue fallando","Se mantiene"))))))))
C23: Pedido Detalle
A24: 11 | B24: 11 | C24: Validar Estatus del Pedido | D24: Debe estar en estado Normal | F24: No cumple | G24: El estatus del pedido aparece como: NINGUNO | H24: Corregido | O24: =IF(M24<>"",M24,IF(K24<>"",K24,IF(I24<>"",I24,""))) | P24: =IF(O24="","",IF(O24="PENDIENTE","Pendiente",IF(O24="NO EJECUTABLE","No ejecutable",IF(O24="VERIFICAR","Por verificar",IF(AND(F24="No cumple",O24="CUMPLE"),"Mejora",IF(AND(F24="No cumple",O24="PARCIAL"),"Mejora parcial",IF(AND(OR(F24="Cumple",F24="Sin ejecutar"),OR(O24="NO CUMPLE",O24="PARCIAL")),IF(F24="Cumple","Regresión","Falla nueva"),IF(AND(F24="No cumple",O24="NO CUMPLE"),"Sigue fallando","Se mantiene"))))))))
A25: 12 | B25: 12 | C25: Seleccionar Tipo de Personal Operativo | D25: Validar que sólo se muestre Operativo por default ser un pedido de seguridad | F25: Cumple | O25: =IF(M25<>"",M25,IF(K25<>"",K25,IF(I25<>"",I25,""))) | P25: =IF(O25="","",IF(O25="PENDIENTE","Pendiente",IF(O25="NO EJECUTABLE","No ejecutable",IF(O25="VERIFICAR","Por verificar",IF(AND(F25="No cumple",O25="CUMPLE"),"Mejora",IF(AND(F25="No cumple",O25="PARCIAL"),"Mejora parcial",IF(AND(OR(F25="Cumple",F25="Sin ejecutar"),OR(O25="NO CUMPLE",O25="PARCIAL")),IF(F25="Cumple","Regresión","Falla nueva"),IF(AND(F25="No cumple",O25="NO CUMPLE"),"Sigue fallando","Se mantiene"))))))))
A26: 13 | B26: 13 | C26: Validar que Tïtulo, Lugar de Cita, Facturable vienen prerellenos | D26: Validar que se muestran todos los productos de Seguridad | E26: Descripción y esperado no corresponden. | F26: No cumple | G26: Revisar filtros en el catálogo de productos para facilitar la consulta. El campo de facturable no viene prerelleno | H26: Corregido | O26: =IF(M26<>"",M26,IF(K26<>"",K26,IF(I26<>"",I26,""))) | P26: =IF(O26="","",IF(O26="PENDIENTE","Pendiente",IF(O26="NO EJECUTABLE","No ejecutable",IF(O26="VERIFICAR","Por verificar",IF(AND(F26="No cumple",O26="CUMPLE"),"Mejora",IF(AND(F26="No cumple",O26="PARCIAL"),"Mejora parcial",IF(AND(OR(F26="Cumple",F26="Sin ejecutar"),OR(O26="NO CUMPLE",O26="PARCIAL")),IF(F26="Cumple","Regresión","Falla nueva"),IF(AND(F26="No cumple",O26="NO CUMPLE"),"Sigue fallando","Se mantiene"))))))))
A27: 14 | B27: 14 | C27: Seleccionar Producto Seguridad-MA | F27: Cumple | O27: =IF(M27<>"",M27,IF(K27<>"",K27,IF(I27<>"",I27,""))) | P27: =IF(O27="","",IF(O27="PENDIENTE","Pendiente",IF(O27="NO EJECUTABLE","No ejecutable",IF(O27="VERIFICAR","Por verificar",IF(AND(F27="No cumple",O27="CUMPLE"),"Mejora",IF(AND(F27="No cumple",O27="PARCIAL"),"Mejora parcial",IF(AND(OR(F27="Cumple",F27="Sin ejecutar"),OR(O27="NO CUMPLE",O27="PARCIAL")),IF(F27="Cumple","Regresión","Falla nueva"),IF(AND(F27="No cumple",O27="NO CUMPLE"),"Sigue fallando","Se mantiene"))))))))
A28: 15 | B28: 15 | C28: Validar que el sistema muestra las horas por turno de ese producto | D28: Se muestra 1 turno por 8 horas | F28: No cumple | G28: No muestra la infromación | H28: Corregido / Listo | O28: =IF(M28<>"",M28,IF(K28<>"",K28,IF(I28<>"",I28,""))) | P28: =IF(O28="","",IF(O28="PENDIENTE","Pendiente",IF(O28="NO EJECUTABLE","No ejecutable",IF(O28="VERIFICAR","Por verificar",IF(AND(F28="No cumple",O28="CUMPLE"),"Mejora",IF(AND(F28="No cumple",O28="PARCIAL"),"Mejora parcial",IF(AND(OR(F28="Cumple",F28="Sin ejecutar"),OR(O28="NO CUMPLE",O28="PARCIAL")),IF(F28="Cumple","Regresión","Falla nueva"),IF(AND(F28="No cumple",O28="NO CUMPLE"),"Sigue fallando","Se mantiene"))))))))
A29: 16 | B29: 16 | C29: Poner Cantidad 2 y Turnos 3 | F29: Cumple | O29: =IF(M29<>"",M29,IF(K29<>"",K29,IF(I29<>"",I29,""))) | P29: =IF(O29="","",IF(O29="PENDIENTE","Pendiente",IF(O29="NO EJECUTABLE","No ejecutable",IF(O29="VERIFICAR","Por verificar",IF(AND(F29="No cumple",O29="CUMPLE"),"Mejora",IF(AND(F29="No cumple",O29="PARCIAL"),"Mejora parcial",IF(AND(OR(F29="Cumple",F29="Sin ejecutar"),OR(O29="NO CUMPLE",O29="PARCIAL")),IF(F29="Cumple","Regresión","Falla nueva"),IF(AND(F29="No cumple",O29="NO CUMPLE"),"Sigue fallando","Se mantiene"))))))))
A30: 17 | B30: 17 | C30: Seleccionar cualquier Fecha de Cita | F30: Cumple | O30: =IF(M30<>"",M30,IF(K30<>"",K30,IF(I30<>"",I30,""))) | P30: =IF(O30="","",IF(O30="PENDIENTE","Pendiente",IF(O30="NO EJECUTABLE","No ejecutable",IF(O30="VERIFICAR","Por verificar",IF(AND(F30="No cumple",O30="CUMPLE"),"Mejora",IF(AND(F30="No cumple",O30="PARCIAL"),"Mejora parcial",IF(AND(OR(F30="Cumple",F30="Sin ejecutar"),OR(O30="NO CUMPLE",O30="PARCIAL")),IF(F30="Cumple","Regresión","Falla nueva"),IF(AND(F30="No cumple",O30="NO CUMPLE"),"Sigue fallando","Se mantiene"))))))))
A31: 18 | B31: 18 | C31: Seleccionar una fecha de liberación posterior | D31: El sistema debe de mostrar una alerta por que no puede ser la fecha de liberación posterior a la fecha de cita | F31: Cumple | O31: =IF(M31<>"",M31,IF(K31<>"",K31,IF(I31<>"",I31,""))) | P31: =IF(O31="","",IF(O31="PENDIENTE","Pendiente",IF(O31="NO EJECUTABLE","No ejecutable",IF(O31="VERIFICAR","Por verificar",IF(AND(F31="No cumple",O31="CUMPLE"),"Mejora",IF(AND(F31="No cumple",O31="PARCIAL"),"Mejora parcial",IF(AND(OR(F31="Cumple",F31="Sin ejecutar"),OR(O31="NO CUMPLE",O31="PARCIAL")),IF(F31="Cumple","Regresión","Falla nueva"),IF(AND(F31="No cumple",O31="NO CUMPLE"),"Sigue fallando","Se mantiene"))))))))
A32: 19 | B32: 19 | C32: Seleccionar una fecha correcta de liberación | F32: Cumple | O32: =IF(M32<>"",M32,IF(K32<>"",K32,IF(I32<>"",I32,""))) | P32: =IF(O32="","",IF(O32="PENDIENTE","Pendiente",IF(O32="NO EJECUTABLE","No ejecutable",IF(O32="VERIFICAR","Por verificar",IF(AND(F32="No cumple",O32="CUMPLE"),"Mejora",IF(AND(F32="No cumple",O32="PARCIAL"),"Mejora parcial",IF(AND(OR(F32="Cumple",F32="Sin ejecutar"),OR(O32="NO CUMPLE",O32="PARCIAL")),IF(F32="Cumple","Regresión","Falla nueva"),IF(AND(F32="No cumple",O32="NO CUMPLE"),"Sigue fallando","Se mantiene"))))))))
A33: 20 | B33: 20 | C33: En presentación por producto, validar que sólo muentren las de la unidad de negocio | F33: Cumple | O33: =IF(M33<>"",M33,IF(K33<>"",K33,IF(I33<>"",I33,""))) | P33: =IF(O33="","",IF(O33="PENDIENTE","Pendiente",IF(O33="NO EJECUTABLE","No ejecutable",IF(O33="VERIFICAR","Por verificar",IF(AND(F33="No cumple",O33="CUMPLE"),"Mejora",IF(AND(F33="No cumple",O33="PARCIAL"),"Mejora parcial",IF(AND(OR(F33="Cumple",F33="Sin ejecutar"),OR(O33="NO CUMPLE",O33="PARCIAL")),IF(F33="Cumple","Regresión","Falla nueva"),IF(AND(F33="No cumple",O33="NO CUMPLE"),"Sigue fallando","Se mantiene"))))))))
A34: 21 | B34: 21 | C34: Completar con similares - Marcar SI | F34: Cumple | O34: =IF(M34<>"",M34,IF(K34<>"",K34,IF(I34<>"",I34,""))) | P34: =IF(O34="","",IF(O34="PENDIENTE","Pendiente",IF(O34="NO EJECUTABLE","No ejecutable",IF(O34="VERIFICAR","Por verificar",IF(AND(F34="No cumple",O34="CUMPLE"),"Mejora",IF(AND(F34="No cumple",O34="PARCIAL"),"Mejora parcial",IF(AND(OR(F34="Cumple",F34="Sin ejecutar"),OR(O34="NO CUMPLE",O34="PARCIAL")),IF(F34="Cumple","Regresión","Falla nueva"),IF(AND(F34="No cumple",O34="NO CUMPLE"),"Sigue fallando","Se mantiene"))))))))
A35: 22 | B35: 22 | C35: Agregar registro | D35: Validamos que se muestra la Matriz de información (Fecha, hora, productos, Turnos, Totales (personal y monto)) | F35: Cumple | G35: Revisar la validación de turnos por cantidad y si el nombre de producto está en la matriz en la parte de descripción | H35: EN PROCESO | O35: =IF(M35<>"",M35,IF(K35<>"",K35,IF(I35<>"",I35,""))) | P35: =IF(O35="","",IF(O35="PENDIENTE","Pendiente",IF(O35="NO EJECUTABLE","No ejecutable",IF(O35="VERIFICAR","Por verificar",IF(AND(F35="No cumple",O35="CUMPLE"),"Mejora",IF(AND(F35="No cumple",O35="PARCIAL"),"Mejora parcial",IF(AND(OR(F35="Cumple",F35="Sin ejecutar"),OR(O35="NO CUMPLE",O35="PARCIAL")),IF(F35="Cumple","Regresión","Falla nueva"),IF(AND(F35="No cumple",O35="NO CUMPLE"),"Sigue fallando","Se mantiene"))))))))
A36: 23 | B36: 23 | C36: Al posicionarse sobre el producto debe mostrar | D36: ID, Lugar de Cita, Fecha Cita, Fecha Fin Cita, Fecha Liberación, Completar con Similares, Cantidad Reservados, Cantidad Reservados Real, Cantidad Reservados con preasignación, Porcentaje Completo, Fase del Evento, Presentación | F36: No cumple | G36: Revisar que estén en las tres pestañas todos los conceptos mencioandos, algunos los encontré, otros no. | H36: EN PROCESO | O36: =IF(M36<>"",M36,IF(K36<>"",K36,IF(I36<>"",I36,""))) | P36: =IF(O36="","",IF(O36="PENDIENTE","Pendiente",IF(O36="NO EJECUTABLE","No ejecutable",IF(O36="VERIFICAR","Por verificar",IF(AND(F36="No cumple",O36="CUMPLE"),"Mejora",IF(AND(F36="No cumple",O36="PARCIAL"),"Mejora parcial",IF(AND(OR(F36="Cumple",F36="Sin ejecutar"),OR(O36="NO CUMPLE",O36="PARCIAL")),IF(F36="Cumple","Regresión","Falla nueva"),IF(AND(F36="No cumple",O36="NO CUMPLE"),"Sigue fallando","Se mantiene"))))))))
A37: 24 | B37: 24 | C37: En la flecha con los turnos debe mostrar | D37: Editar, Reservaciones, Cancelar y Liberar | F37: No cumple | G37: revisar punto una vez más con ayuda de Leo.. | H37: EN PROCESO | O37: =IF(M37<>"",M37,IF(K37<>"",K37,IF(I37<>"",I37,""))) | P37: =IF(O37="","",IF(O37="PENDIENTE","Pendiente",IF(O37="NO EJECUTABLE","No ejecutable",IF(O37="VERIFICAR","Por verificar",IF(AND(F37="No cumple",O37="CUMPLE"),"Mejora",IF(AND(F37="No cumple",O37="PARCIAL"),"Mejora parcial",IF(AND(OR(F37="Cumple",F37="Sin ejecutar"),OR(O37="NO CUMPLE",O37="PARCIAL")),IF(F37="Cumple","Regresión","Falla nueva"),IF(AND(F37="No cumple",O37="NO CUMPLE"),"Sigue fallando","Se mantiene"))))))))
A38: 25 | B38: 25 | C38: Pulsar sobre Cancelar Pedido | D38: Validar que el estatus pasa a estado Cancelado | F38: No cumple | G38: Se realizó correctamente la cancelación, sin emabrgo, nos mostro un error al querer regresar al menu de pedidos. Favor de revisar. | H38: Corregido | O38: =IF(M38<>"",M38,IF(K38<>"",K38,IF(I38<>"",I38,""))) | P38: =IF(O38="","",IF(O38="PENDIENTE","Pendiente",IF(O38="NO EJECUTABLE","No ejecutable",IF(O38="VERIFICAR","Por verificar",IF(AND(F38="No cumple",O38="CUMPLE"),"Mejora",IF(AND(F38="No cumple",O38="PARCIAL"),"Mejora parcial",IF(AND(OR(F38="Cumple",F38="Sin ejecutar"),OR(O38="NO CUMPLE",O38="PARCIAL")),IF(F38="Cumple","Regresión","Falla nueva"),IF(AND(F38="No cumple",O38="NO CUMPLE"),"Sigue fallando","Se mantiene"))))))))

Sheet ESC-02
A1: ESC-02 — Pedido PRG-Producción con complejidad y días show
A2: Núm. original | B2: Escenario 2 | I2: Pasos | J2: =COUNT(A13:A39)
A3: Módulo | B3: Pedidos | I3: Ejecutados (último) | J3: =COUNTIF(O13:O39,"?*")
A4: Objetivo (propuesto, validar) | B4: Validar un pedido PRG con complejidad y días de show: personal Staff, bloques por producto y presupuesto ligado a complejidad. | I4: CUMPLE (último) | J4: =COUNTIF(O13:O39,"CUMPLE")
A5: Funcionalidades | B5: Complejidad · duración en días de show · tipo de personal Staff · catálogo PRG · jornada · fase de evento · bloques · presupuesto día | I5: % cumplimiento | J5: =IF(J2=0,0,J4/J2)
A6: Dependencias / datos | B6: —
A7: Sesión sugerida | B7: S02
A8: ⚠ Calidad del caso | B8: Paso 5 esperado dice 'UN de seguridad' (copiado del Esc. 1). Paso 7 texto corrupto ('movi+E10:F10miento'). Paso 8 es Servicio Interno pero el esperado habla de Pedido. Paso 18: 'nos' probablemente es 'no'.
A9: Notas originales | B9: —
F11: CORRIDA LEGADO (HUMANOS) | I11: CICLO CLAUDE CODE: probar → corregir → re-probar
A12: # | B12: Paso orig. | C12: Descripción | D12: Resultado esperado | E12: ⚠ Calidad | F12: Legado: Resultado | G12: Legado: Observación | H12: Legado: Corrección | I12: R1 Resultado | J12: R1 Hallazgo / Obs. | K12: R2 Resultado | L12: R2 Hallazgo / Obs. | M12: R3 Resultado | N12: R3 Hallazgo / Obs. | O12: Último resultado | P12: Comparativo
A13: 1 | B13: 1 | C13: Crear un nuevo pedido | F13: Cumple | I13: CUMPLE | O13: =IF(M13<>"",M13,IF(K13<>"",K13,IF(I13<>"",I13,""))) | P13: =IF(O13="","",IF(O13="PENDIENTE","Pendiente",IF(O13="NO EJECUTABLE","No ejecutable",IF(O13="VERIFICAR","Por verificar",IF(AND(F13="No cumple",O13="CUMPLE"),"Mejora",IF(AND(F13="No cumple",O13="PARCIAL"),"Mejora parcial",IF(AND(OR(F13="Cumple",F13="Sin ejecutar"),OR(O13="NO CUMPLE",O13="PARCIAL")),IF(F13="Cumple","Regresión","Falla nueva"),IF(AND(F13="No cumple",O13="NO CUMPLE"),"Sigue fallando","Se mantiene"))))))))
A14: 2 | B14: 2 | C14: Seleccionar cliente Ocesa | F14: Cumple | I14: CUMPLE | O14: =IF(M14<>"",M14,IF(K14<>"",K14,IF(I14<>"",I14,""))) | P14: =IF(O14="","",IF(O14="PENDIENTE","Pendiente",IF(O14="NO EJECUTABLE","No ejecutable",IF(O14="VERIFICAR","Por verificar",IF(AND(F14="No cumple",O14="CUMPLE"),"Mejora",IF(AND(F14="No cumple",O14="PARCIAL"),"Mejora parcial",IF(AND(OR(F14="Cumple",F14="Sin ejecutar"),OR(O14="NO CUMPLE",O14="PARCIAL")),IF(F14="Cumple","Regresión","Falla nueva"),IF(AND(F14="No cumple",O14="NO CUMPLE"),"Sigue fallando","Se mantiene"))))))))
A15: 3 | B15: 3 | C15: Validar lista de contactos | D15: Los contactos mostrados deben pertenecer al cliente Ocesa | F15: Cumple | I15: CUMPLE | J15: Contacto unico verificado en BD (Laura Mendez Ruiz, tc_contactos_cliente) | O15: =IF(M15<>"",M15,IF(K15<>"",K15,IF(I15<>"",I15,""))) | P15: =IF(O15="","",IF(O15="PENDIENTE","Pendiente",IF(O15="NO EJECUTABLE","No ejecutable",IF(O15="VERIFICAR","Por verificar",IF(AND(F15="No cumple",O15="CUMPLE"),"Mejora",IF(AND(F15="No cumple",O15="PARCIAL"),"Mejora parcial",IF(AND(OR(F15="Cumple",F15="Sin ejecutar"),OR(O15="NO CUMPLE",O15="PARCIAL")),IF(F15="Cumple","Regresión","Falla nueva"),IF(AND(F15="No cumple",O15="NO CUMPLE"),"Sigue fallando","Se mantiene"))))))))
A16: 4 | B16: 4 | C16: Seleccionar un evento | F16: Cumple | I16: CUMPLE | J16: Titulo del pedido autocompleta desde el evento y es editable. Fecha del evento NO autocompleta (UX_MENOR); se capturo a mano la fecha real del evento. | O16: =IF(M16<>"",M16,IF(K16<>"",K16,IF(I16<>"",I16,""))) | P16: =IF(O16="","",IF(O16="PENDIENTE","Pendiente",IF(O16="NO EJECUTABLE","No ejecutable",IF(O16="VERIFICAR","Por verificar",IF(AND(F16="No cumple",O16="CUMPLE"),"Mejora",IF(AND(F16="No cumple",O16="PARCIAL"),"Mejora parcial",IF(AND(OR(F16="Cumple",F16="Sin ejecutar"),OR(O16="NO CUMPLE",O16="PARCIAL")),IF(F16="Cumple","Regresión","Falla nueva"),IF(AND(F16="No cumple",O16="NO CUMPLE"),"Sigue fallando","Se mantiene"))))))))
A17: 5 | B17: 5 | C17: Seleccionar UN PRG | D17: El sistema despliega los PEPS de la UN de seguridad, y la sociedad pagadora (en este caso Lobo) | E17: Esperado copiado ('UN de seguridad'). | F17: Cumple | I17: CUMPLE | J17: 9 PEPs reales de PRG mostrados correctamente. Sociedad pagadora no autocompleta (gap ya conocido en CLAUDE.md Sec.11, no es de este caso). | O17: =IF(M17<>"",M17,IF(K17<>"",K17,IF(I17<>"",I17,""))) | P17: =IF(O17="","",IF(O17="PENDIENTE","Pendiente",IF(O17="NO EJECUTABLE","No ejecutable",IF(O17="VERIFICAR","Por verificar",IF(AND(F17="No cumple",O17="CUMPLE"),"Mejora",IF(AND(F17="No cumple",O17="PARCIAL"),"Mejora parcial",IF(AND(OR(F17="Cumple",F17="Sin ejecutar"),OR(O17="NO CUMPLE",O17="PARCIAL")),IF(F17="Cumple","Regresión","Falla nueva"),IF(AND(F17="No cumple",O17="NO CUMPLE"),"Sigue fallando","Se mantiene"))))))))
A18: 6 | B18: 6 | C18: Seleccionar el PEPS asociado a la UN | D18: El sistema me muestra el nombre y la dirección del inmueble | F18: Cumple | I18: PARCIAL | J18: Sitio/Lugar de cita no autocompletan: los 9 PEPs de PRG no tienen sociedad propia ni lugar predeterminado en BD (dato, no codigo). | O18: =IF(M18<>"",M18,IF(K18<>"",K18,IF(I18<>"",I18,""))) | P18: =IF(O18="","",IF(O18="PENDIENTE","Pendiente",IF(O18="NO EJECUTABLE","No ejecutable",IF(O18="VERIFICAR","Por verificar",IF(AND(F18="No cumple",O18="CUMPLE"),"Mejora",IF(AND(F18="No cumple",O18="PARCIAL"),"Mejora parcial",IF(AND(OR(F18="Cumple",F18="Sin ejecutar"),OR(O18="NO CUMPLE",O18="PARCIAL")),IF(F18="Cumple","Regresión","Falla nueva"),IF(AND(F18="No cumple",O18="NO CUMPLE"),"Sigue fallando","Se mantiene"))))))))
A19: 7 | B19: 7 | C19: Validar tipo de movimiento | D19: El sistema debe mostrar dos tipos de movi+E10:F10miento (Pedido y Servicio Interno) | E19: Texto corrupto en el esperado. | F19: No cumple | G19: Únicamnete muestra "pedido" | H19: Corregido | I19: NO CUMPLE | J19: H-002: UI real muestra 3 tipos (Orden de servicio / Pedido facturable a cliente / Servicio interno); ninguno se llama "Pedido" literal. | O19: =IF(M19<>"",M19,IF(K19<>"",K19,IF(I19<>"",I19,""))) | P19: =IF(O19="","",IF(O19="PENDIENTE","Pendiente",IF(O19="NO EJECUTABLE","No ejecutable",IF(O19="VERIFICAR","Por verificar",IF(AND(F19="No cumple",O19="CUMPLE"),"Mejora",IF(AND(F19="No cumple",O19="PARCIAL"),"Mejora parcial",IF(AND(OR(F19="Cumple",F19="Sin ejecutar"),OR(O19="NO CUMPLE",O19="PARCIAL")),IF(F19="Cumple","Regresión","Falla nueva"),IF(AND(F19="No cumple",O19="NO CUMPLE"),"Sigue fallando","Se mantiene"))))))))
A20: 8 | B20: 8 | C20: Seleccionar Tipo de movimiento Servicio Interno | D20: EL tipo Pedido se factura (validar posteriormente) | E20: Servicio Interno con esperado de Pedido. | F20: No cumple | G20: Al no poder seleccionar el tipo de movimiento no sabemos si afecta en el procedimiento. Nos aparece que no es facturable, pero se puede cambiar. | H20: Corregido | I20: PARCIAL | J20: H-002: "Facturable" va embebido en el texto de la opcion elegida; no existe un campo separado editable. | O20: =IF(M20<>"",M20,IF(K20<>"",K20,IF(I20<>"",I20,""))) | P20: =IF(O20="","",IF(O20="PENDIENTE","Pendiente",IF(O20="NO EJECUTABLE","No ejecutable",IF(O20="VERIFICAR","Por verificar",IF(AND(F20="No cumple",O20="CUMPLE"),"Mejora",IF(AND(F20="No cumple",O20="PARCIAL"),"Mejora parcial",IF(AND(OR(F20="Cumple",F20="Sin ejecutar"),OR(O20="NO CUMPLE",O20="PARCIAL")),IF(F20="Cumple","Regresión","Falla nueva"),IF(AND(F20="No cumple",O20="NO CUMPLE"),"Sigue fallando","Se mantiene"))))))))
A21: 9 | B21: 9 | C21: Seleccionar Complejidad Foro Sol - 1 Día de Show | D21: Validar que el sistema sólo muestra las 6 complejidades del catálogo | F21: No cumple | G21: únicamnete muestra 3 opciones del foro sol, y dos son iguales. | H21: Corregido | I21: CUMPLE | J21: 6 complejidades reales confirmadas en combo, sin duplicados. | O21: =IF(M21<>"",M21,IF(K21<>"",K21,IF(I21<>"",I21,""))) | P21: =IF(O21="","",IF(O21="PENDIENTE","Pendiente",IF(O21="NO EJECUTABLE","No ejecutable",IF(O21="VERIFICAR","Por verificar",IF(AND(F21="No cumple",O21="CUMPLE"),"Mejora",IF(AND(F21="No cumple",O21="PARCIAL"),"Mejora parcial",IF(AND(OR(F21="Cumple",F21="Sin ejecutar"),OR(O21="NO CUMPLE",O21="PARCIAL")),IF(F21="Cumple","Regresión","Falla nueva"),IF(AND(F21="No cumple",O21="NO CUMPLE"),"Sigue fallando","Se mantiene"))))))))
A22: 10 | B22: 10 | C22: Indicar 1 día de show en el campo Duración del Evento | F22: Cumple | I22: CUMPLE | J22: Campo es compuesto (Tipo de duracion + Dias), no un unico "Duracion del Evento". Se uso Shows Sueltos + 1 dia. | O22: =IF(M22<>"",M22,IF(K22<>"",K22,IF(I22<>"",I22,""))) | P22: =IF(O22="","",IF(O22="PENDIENTE","Pendiente",IF(O22="NO EJECUTABLE","No ejecutable",IF(O22="VERIFICAR","Por verificar",IF(AND(F22="No cumple",O22="CUMPLE"),"Mejora",IF(AND(F22="No cumple",O22="PARCIAL"),"Mejora parcial",IF(AND(OR(F22="Cumple",F22="Sin ejecutar"),OR(O22="NO CUMPLE",O22="PARCIAL")),IF(F22="Cumple","Regresión","Falla nueva"),IF(AND(F22="No cumple",O22="NO CUMPLE"),"Sigue fallando","Se mantiene"))))))))
A23: 11 | B23: 11 | C23: En el campo Permitir Cancelar, seleccionar NO | F23: Cumple | I23: CUMPLE | J23: Click real en checkbox confirmado. | O23: =IF(M23<>"",M23,IF(K23<>"",K23,IF(I23<>"",I23,""))) | P23: =IF(O23="","",IF(O23="PENDIENTE","Pendiente",IF(O23="NO EJECUTABLE","No ejecutable",IF(O23="VERIFICAR","Por verificar",IF(AND(F23="No cumple",O23="CUMPLE"),"Mejora",IF(AND(F23="No cumple",O23="PARCIAL"),"Mejora parcial",IF(AND(OR(F23="Cumple",F23="Sin ejecutar"),OR(O23="NO CUMPLE",O23="PARCIAL")),IF(F23="Cumple","Regresión","Falla nueva"),IF(AND(F23="No cumple",O23="NO CUMPLE"),"Sigue fallando","Se mantiene"))))))))
A24: 12 | B24: 12 | C24: Pulsar Aceptar | D24: El sistema genera un número consecutivo de pedido. | F24: Cumple | I24: CUMPLE | J24: Precondicion critica VERIFICADA EN BD (pedido #200): tipo_complejidad_id, tipo_duracion_id, duracion_dias=1 y permitir_cancelaciones=false guardados correctamente. | O24: =IF(M24<>"",M24,IF(K24<>"",K24,IF(I24<>"",I24,""))) | P24: =IF(O24="","",IF(O24="PENDIENTE","Pendiente",IF(O24="NO EJECUTABLE","No ejecutable",IF(O24="VERIFICAR","Por verificar",IF(AND(F24="No cumple",O24="CUMPLE"),"Mejora",IF(AND(F24="No cumple",O24="PARCIAL"),"Mejora parcial",IF(AND(OR(F24="Cumple",F24="Sin ejecutar"),OR(O24="NO CUMPLE",O24="PARCIAL")),IF(F24="Cumple","Regresión","Falla nueva"),IF(AND(F24="No cumple",O24="NO CUMPLE"),"Sigue fallando","Se mantiene"))))))))
C25: Pedido Detalle | I25: NO CUMPLE | J25: H-003: no existe texto "Staff"/"Operativo" en ningun campo. Catalogo real tiene 3 categorias (freelance/interno/planta).
A26: 13 | B26: 13 | C26: Tipo de personal | D26: Validar que muestra Staff y Operativo | F26: Cumple | I26: CUMPLE | J26: H-003: "Personal de planta" (clave=staff, el equivalente funcional real de Staff) SI es seleccionable y activa el gating real de negocio -- verificado releyendo el codigo y reprobando en vivo. | O26: =IF(M26<>"",M26,IF(K26<>"",K26,IF(I26<>"",I26,""))) | P26: =IF(O26="","",IF(O26="PENDIENTE","Pendiente",IF(O26="NO EJECUTABLE","No ejecutable",IF(O26="VERIFICAR","Por verificar",IF(AND(F26="No cumple",O26="CUMPLE"),"Mejora",IF(AND(F26="No cumple",O26="PARCIAL"),"Mejora parcial",IF(AND(OR(F26="Cumple",F26="Sin ejecutar"),OR(O26="NO CUMPLE",O26="PARCIAL")),IF(F26="Cumple","Regresión","Falla nueva"),IF(AND(F26="No cumple",O26="NO CUMPLE"),"Sigue fallando","Se mantiene"))))))))
A27: 14 | B27: 14 | C27: Seleccionar Staff como Tipo de Personal | F27: Cumple | I27: NO CUMPLE | J27: H-005: con Staff (clave real) seleccionado, el combo de Producto queda VACIO -- ningun puesto matricial de PRG tiene tarifa en tp_sueldos_matriciales (0 filas confirmadas en BD). | O27: =IF(M27<>"",M27,IF(K27<>"",K27,IF(I27<>"",I27,""))) | P27: =IF(O27="","",IF(O27="PENDIENTE","Pendiente",IF(O27="NO EJECUTABLE","No ejecutable",IF(O27="VERIFICAR","Por verificar",IF(AND(F27="No cumple",O27="CUMPLE"),"Mejora",IF(AND(F27="No cumple",O27="PARCIAL"),"Mejora parcial",IF(AND(OR(F27="Cumple",F27="Sin ejecutar"),OR(O27="NO CUMPLE",O27="PARCIAL")),IF(F27="Cumple","Regresión","Falla nueva"),IF(AND(F27="No cumple",O27="NO CUMPLE"),"Sigue fallando","Se mantiene"))))))))
A28: 15 | B28: 15 | C28: Producto: Asistente Operador PRG - IN | D28: Validar que el catálogo mostrado es el de PRG | F28: No cumple | G28: El producto asistente operador PRG-IN no aparece si tomamos el tipo de personal staff, pero si tomamos el tipo de personal operativo sí aparece la opción | H28: BASE DE DATOS | I28: NO EJECUTABLE | J28: H-005: bloqueado, no hay producto Staff seleccionable para poder validar la jornada. | O28: =IF(M28<>"",M28,IF(K28<>"",K28,IF(I28<>"",I28,""))) | P28: =IF(O28="","",IF(O28="PENDIENTE","Pendiente",IF(O28="NO EJECUTABLE","No ejecutable",IF(O28="VERIFICAR","Por verificar",IF(AND(F28="No cumple",O28="CUMPLE"),"Mejora",IF(AND(F28="No cumple",O28="PARCIAL"),"Mejora parcial",IF(AND(OR(F28="Cumple",F28="Sin ejecutar"),OR(O28="NO CUMPLE",O28="PARCIAL")),IF(F28="Cumple","Regresión","Falla nueva"),IF(AND(F28="No cumple",O28="NO CUMPLE"),"Sigue fallando","Se mantiene"))))))))
A29: 16 | B29: 16 | C29: Validar la jornada | D29: Debe mostrar 1 turno por 12 horas, que es el turno asociado al producto | F29: No cumple | G29: En ninguna parte aparece los turnos y las horas. | H29: Corregido | I29: PARCIAL | J29: H-005: la UI SI acepta fecha de cita y liberacion sin error, pero el renglon nunca se persiste por la causa raiz de H-005. | O29: =IF(M29<>"",M29,IF(K29<>"",K29,IF(I29<>"",I29,""))) | P29: =IF(O29="","",IF(O29="PENDIENTE","Pendiente",IF(O29="NO EJECUTABLE","No ejecutable",IF(O29="VERIFICAR","Por verificar",IF(AND(F29="No cumple",O29="CUMPLE"),"Mejora",IF(AND(F29="No cumple",O29="PARCIAL"),"Mejora parcial",IF(AND(OR(F29="Cumple",F29="Sin ejecutar"),OR(O29="NO CUMPLE",O29="PARCIAL")),IF(F29="Cumple","Regresión","Falla nueva"),IF(AND(F29="No cumple",O29="NO CUMPLE"),"Sigue fallando","Se mantiene"))))))))
A30: 17 | B30: 17 | C30: Seleccionar una fecha de cita y de liberación | F30: Cumple | I30: CUMPLE | J30: Combo Presentacion por producto solo con "-- sin presentacion --", confirmado 2 veces. | O30: =IF(M30<>"",M30,IF(K30<>"",K30,IF(I30<>"",I30,""))) | P30: =IF(O30="","",IF(O30="PENDIENTE","Pendiente",IF(O30="NO EJECUTABLE","No ejecutable",IF(O30="VERIFICAR","Por verificar",IF(AND(F30="No cumple",O30="CUMPLE"),"Mejora",IF(AND(F30="No cumple",O30="PARCIAL"),"Mejora parcial",IF(AND(OR(F30="Cumple",F30="Sin ejecutar"),OR(O30="NO CUMPLE",O30="PARCIAL")),IF(F30="Cumple","Regresión","Falla nueva"),IF(AND(F30="No cumple",O30="NO CUMPLE"),"Sigue fallando","Se mantiene"))))))))
A31: 18 | B31: 18 | C31: Presentación por producto | D31: Validar que nos se muestran presentaciones | E31: 'nos' → probablemente 'no'. | F31: Cumple | G31: Aumo que en vez de "nos" hace referecnia a no | I31: NO EJECUTABLE | J31: H-005: no se pudo probar con un producto Staff real; inconcluso respecto al auto-seleccionado de "No Aplica". | O31: =IF(M31<>"",M31,IF(K31<>"",K31,IF(I31<>"",I31,""))) | P31: =IF(O31="","",IF(O31="PENDIENTE","Pendiente",IF(O31="NO EJECUTABLE","No ejecutable",IF(O31="VERIFICAR","Por verificar",IF(AND(F31="No cumple",O31="CUMPLE"),"Mejora",IF(AND(F31="No cumple",O31="PARCIAL"),"Mejora parcial",IF(AND(OR(F31="Cumple",F31="Sin ejecutar"),OR(O31="NO CUMPLE",O31="PARCIAL")),IF(F31="Cumple","Regresión","Falla nueva"),IF(AND(F31="No cumple",O31="NO CUMPLE"),"Sigue fallando","Se mantiene"))))))))
A32: 19 | B32: 19 | C32: Fase del evento | D32: Al ser Staff con complejidad y días de show debe mostrar No Aplica | F32: No cumple | G32: En efecto noa plica, pero tanto en el escenario 1 y 2 aparecía así. Además se continuó conpersonal operativo y no de staff | H32: EN PROCESO | I32: NO EJECUTABLE | J32: H-005 / H-006 (ver CLAUDE.md Sec.11): con producto sin puesto el sistema SI valida claramente "Elegi un producto (define el puesto)" -- no es falla silenciosa. Con Staff real, el combo esta vacio por H-005. | O32: =IF(M32<>"",M32,IF(K32<>"",K32,IF(I32<>"",I32,""))) | P32: =IF(O32="","",IF(O32="PENDIENTE","Pendiente",IF(O32="NO EJECUTABLE","No ejecutable",IF(O32="VERIFICAR","Por verificar",IF(AND(F32="No cumple",O32="CUMPLE"),"Mejora",IF(AND(F32="No cumple",O32="PARCIAL"),"Mejora parcial",IF(AND(OR(F32="Cumple",F32="Sin ejecutar"),OR(O32="NO CUMPLE",O32="PARCIAL")),IF(F32="Cumple","Regresión","Falla nueva"),IF(AND(F32="No cumple",O32="NO CUMPLE"),"Sigue fallando","Se mantiene"))))))))
